#VRML_SIM R2021a utf8
WorldInfo {
  gravity 200
  ERP 0.8
  basicTimeStep 1
  coordinateSystem "NUE"
  contactProperties [
    ContactProperties {
      coulombFriction [
        8
      ]
      bounce 0
      bounceVelocity 1
      softERP 0.85
      softCFM 1e-05
    }
  ]
}
Viewpoint {
  orientation 0.2081297499331315 -0.959226700339337 -0.19122276158679394 4.688040701323383
  position 1.8356134102970625 1.0758875207119838 0.17317125538014333
}
DEF OBSTACULO SolidBox {
  translation -0.217671 0.07 -0.173217
  rotation 0 1 0 1.0472
  size 0.01 0.1 0.3
}
TexturedBackground {
  texture "stadium"
  skyColor [
    0.1 0.5 1
  ]
}
TexturedBackgroundLight {
  texture "stadium"
  luminosity 2
}
DEF ARENA Solid {
  translation -0.504138 -0.015 0.34325
  children [
    Shape {
      appearance Appearance {
        material Material {
          diffuseColor 0 0 0
        }
        texture ImageTexture {
          url [
            ""
          ]
        }
        textureTransform TextureTransform {
          center -0.45 -0.45
          scale 0.9 0.9
        }
      }
      geometry Cylinder {
        height 0.05
        radius 0.77
      }
    }
  ]
  name "solid(2)"
  boundingObject Cylinder {
    height 0.05
    radius 0.77
  }
}
Robot {
  translation -0.8938890883560732 0.03249471159965897 0.7712450179554028
  rotation -0.0027296994818501535 -0.9999683539284748 0.007472608802506454 -2.443703907105059
  children [
    DEF EDGE_RIGHT DistanceSensor {
      translation -0.083748 -0.006999999999999999 0.146763
      rotation 0 0 1 -1.5707963071795863
      children [
        DEF SENSOR Transform {
          rotation 0 0 1 1.57
          children [
            Shape {
              appearance PBRAppearance {
                baseColor 0.6 0 0
                roughness 1
                metalness 0
              }
              geometry Cylinder {
                height 0.004
                radius 0.008
              }
            }
          ]
        }
      ]
      name "edge right"
      lookupTable [
        0 1024 0
        0.02 1024 0.1
        0.08 0 0.3
      ]
      aperture 1
    }
    DEF EDGE_LEFT DistanceSensor {
      translation 0.076252 -0.006999999999999999 0.146763
      rotation 0 0 1 -1.5707963071795863
      children [
        DEF SENSOR Transform {
          rotation 0 0 1 1.57
          children [
            Shape {
              appearance PBRAppearance {
                baseColor 0.6 0 0
                roughness 1
                metalness 0
              }
              geometry Cylinder {
                height 0.002
                radius 0.008
              }
            }
          ]
        }
      ]
      name "edge left"
      lookupTable [
        0 1024 0
        0.02 1024 0.1
        0.08 0 0.3
      ]
      aperture 1
    }
    Transform {
      translation 0 -0.006 0
      children [
        Transform {
          children [
            Shape {
              appearance Appearance {
                material Material {
                  diffuseColor 0.3 0.3 0.3
                }
              }
              geometry Box {
                size 0.2 0.1 0.2
              }
            }
          ]
        }
        DEF BODY Shape {
          appearance Appearance {
            material Material {
              diffuseColor 0.09999999999999999 0.09999999999999999 0.09999999999999999
              transparency 1
            }
          }
          geometry Box {
            size 0.2 0.03 0.2
          }
        }
      ]
    }
    DEF LEFT_WHEEL HingeJoint {
      jointParameters HingeJointParameters {
        position 3317.302824499596
        anchor 0.06 0 0
      }
      device [
        RotationalMotor {
          name "left wheel motor"
          acceleration 10000
          maxVelocity 250
          maxTorque 100
        }
      ]
      endPoint Solid {
        translation 0.059999999061120475 -2.5300914284759537e-06 -3.6049842997156362e-06
        rotation 0.9999993372392888 0.0009858988268718523 -0.000594579251507312 1.1776496339371412
        children [
          DEF WHEEL Transform {
            rotation 0 0 1 1.5708
            children [
              Shape {
                appearance PBRAppearance {
                  baseColor 0.305882 0.898039 0.25098
                  roughness 1
                  metalness 0
                }
                geometry Cylinder {
                  height 0.02
                  radius 0.0225
                  subdivision 24
                }
              }
            ]
          }
        ]
        boundingObject USE WHEEL
        physics Physics {
          density -1
          mass 0.1
        }
      }
    }
    DEF RIGHT_WHEEL HingeJoint {
      jointParameters HingeJointParameters {
        position 2236.949217902863
        anchor -0.06 0 0
      }
      device [
        RotationalMotor {
          name "right wheel motor"
          acceleration 10000
          maxVelocity 250
          maxTorque 100
        }
      ]
      endPoint Solid {
        translation -0.06000000073736451 -4.104891089116699e-07 3.052328719297434e-06
        rotation 0.9999980469507626 0.0012133129596884253 0.0015601174066244923 4.480103183910347
        children [
          USE WHEEL
        ]
        name "solid(1)"
        boundingObject USE WHEEL
        physics Physics {
          density -1
          mass 0.08
        }
      }
    }
    DEF OPPONENT_RIGHT SharpGP2D120 {
      translation -0.03 0.02 0.11
      rotation 0 1 0 -1.5707953071795862
      name "opponent right"
    }
    DEF OPPONENT_LEFT SharpGP2D120 {
      translation 0.01 0.02 0.11
      rotation 0 1 0 -1.5707953071795862
      name "opponent left"
    }
  ]
  name "Atena"
  boundingObject Transform {
    translation 0 -0.006 0
    children [
      USE BODY
    ]
  }
  physics Physics {
    density -1
    mass 3
    centerOfMass [
      0 0 0
    ]
  }
  rotationStep 0.261799
  controller "main"
}
